<?xml version='1.0'?>

<robot name="my_robot" xmlns:xacro="http://www.ros.org/wiki/xacro">

<xacro:include filename="$(find my_robot)/urdf/my_robot.gazebo" />
<xacro:include filename="$(find my_robot)/urdf/color.gazebo" />
  <material name="blue">
        <color rgba="0 0 1 1"/>
  </material>

  <link name="robot_footprint"></link>

  <joint name="robot_footprint_joint" type="fixed">
    <origin xyz="0 0 0" rpy="0 0 0" />
    <parent link="robot_footprint"/>
    <child link="chassis" />
  </joint>

  <link name='chassis'>
    <pose>0 0 0.1 0 0 0</pose>

    <inertial>
      <mass value="5.0"/>
      <origin xyz="0.0 0 0" rpy=" 0 0 0"/>
      <inertia
          ixx="0.1" ixy="0" ixz="0"
          iyy="0.1" iyz="0"
          izz="0.1"
      />
    </inertial>

    <collision name='collision'>
      <origin xyz="0 0 0" rpy=" 0 0 0"/> 
      <geometry>
        <box size="0.8 0.3 .2"/>
      </geometry>
    </collision>

    <visual name='chassis_visual'>
      <origin xyz="0 0 0" rpy=" 0 0 0"/>
      <geometry>
        <box size="0.8 0.3 .2"/>
      </geometry>
      <material name="blue"/>
    </visual>
  </link>

  <link name="left_wheel_front">
	
	<inertial>
	      <mass value="1.0"/>
	      <origin xyz="0 0 0" rpy=" 1.5707 0 0"/>
      	      <inertia ixx=".1" ixy="0" ixz="0" iyy=".1" iyz="0" izz=".1"/>
    	</inertial>

  	<visual name="left_wheel_front_visual">
		<origin xyz="0 0 0" rpy=" 1.5707 0 0"/>
		<geometry>
			<cylinder length="0.1" radius="0.15"/>
		</geometry>
      		<material name="">
        		<color rgba="0 0 0 1"/>
      		</material>	
	</visual>

  	<collision name="left_wheel_front_collision">
		<origin xyz="0 0 0" rpy=" 1.5707 0 0"/>
		<geometry>
			<cylinder length="0.1" radius="0.15"/>
		</geometry>	
	</collision>
	
  </link>

  <link name="right_wheel_front">
		
	<inertial>
	      <mass value="1.0"/>
	      <origin xyz="0 0 0" rpy=" 1.5707 0 0"/>
      		<inertia ixx="0.1" ixy="0" ixz="0" iyy="0.1" iyz="0" izz="0.1"/>
    	</inertial>
  	<visual name="right_wheel_front_visual">
		<origin xyz="0 0 0" rpy=" 1.5707 0 0"/>
		<geometry>
			<cylinder length="0.1" radius="0.15"/>
		</geometry>	
      		<material name="">
        		<color rgba="0 0 0 1"/>
      		</material>
	</visual>
  	<collision name="right_wheel_front_collision">
		<origin xyz="0 0 0" rpy=" 1.5707 0 0"/>
		<geometry>
			<cylinder length="0.1" radius="0.15"/>
		</geometry>	
	</collision>
  </link>

  <link name="left_wheel_back">
	
	<inertial>
	      <mass value="1.0"/>
	      <origin xyz="0 0 0" rpy=" 1.5707 0 0"/>
      	      <inertia ixx=".1" ixy="0" ixz="0" iyy=".1" iyz="0" izz=".1"/>
    	</inertial>

  	<visual name="left_wheel_back_visual">
		<origin xyz="0 0 0" rpy=" 1.5707 0 0"/>
		<geometry>
			<cylinder length="0.1" radius="0.15"/>
		</geometry>
      		<material name="">
        		<color rgba="0 0 0 1"/>
      		</material>	
	</visual>

  	<collision name="left_wheel_back_collision">
		<origin xyz="0 0 0" rpy=" 1.5707 0 0"/>
		<geometry>
			<cylinder length="0.1" radius="0.15"/>
		</geometry>	
	</collision>
	
  </link>

  <link name="right_wheel_back">
		
	<inertial>
	      <mass value="1.0"/>
	      <origin xyz="0 0 0" rpy=" 1.5707 0 0"/>
      		<inertia ixx="0.1" ixy="0" ixz="0" iyy="0.1" iyz="0" izz="0.1"/>
    	</inertial>
  	<visual name="right_wheel_back_visual">
		<origin xyz="0 0 0" rpy=" 1.5707 0 0"/>
		<geometry>
			<cylinder length="0.1" radius="0.15"/>
		</geometry>
      		<material name="">
        		<color rgba="0 0 0 1"/>
      		</material>	
	</visual>
  	<collision name="right_wheel_back_collision">
		<origin xyz="0 0 0" rpy=" 1.5707 0 0"/>
		<geometry>
			<cylinder length="0.1" radius="0.15"/>
		</geometry>	
	</collision>
  </link>

  <joint type="continuous" name="left_wheel_front_hinge">
    <origin xyz="0.25 0.2 0" rpy="0 0 0"/>
    <child link="left_wheel_front"/>
    <parent link="chassis"/>
    <axis xyz="0 1 0" rpy="0 0 0"/>
    <limit effort="10000" velocity="1000"/>
    <dynamics damping="1.0" friction="1.0"/>
  </joint>

  <joint type="continuous" name="right_wheel_front_hinge">
    <origin xyz="0.25 -0.2 0" rpy="0 0 0"/>
    <child link="right_wheel_front"/>
    <parent link="chassis"/>
    <axis xyz="0 1 0" rpy="0 0 0"/>
    <limit effort="10000" velocity="1000"/>
    <dynamics damping="1.0" friction="1.0"/>
  </joint>

  <joint type="continuous" name="left_wheel_back_hinge">
    <origin xyz="-0.25 0.2 0" rpy="0 0 0"/>
    <child link="left_wheel_back"/>
    <parent link="chassis"/>
    <axis xyz="0 1 0" rpy="0 0 0"/>
    <limit effort="10000" velocity="1000"/>
    <dynamics damping="1.0" friction="1.0"/>
  </joint>

  <joint type="continuous" name="right_wheel_back_hinge">
    <origin xyz="-0.25 -0.2 0" rpy="0 0 0"/>
    <child link="right_wheel_back"/>
    <parent link="chassis"/>
    <axis xyz="0 1 0" rpy="0 0 0"/>
    <limit effort="10000" velocity="1000"/>
    <dynamics damping="1.0" friction="1.0"/>
  </joint>

  <link name="camera">
		
	<inertial>
	      <mass value="0.1"/>
	      <origin xyz="0 0 0" rpy="0 0 0"/>
		<box_inertia m=".1" x="0.05" y="0.05" z=""/>
      		<inertia ixx="1e-6" ixy="0" ixz="0" iyy="1e-6" iyz="0" izz="1e-6"/>
    	</inertial>
  	<visual name="camera_visual">
		<origin xyz="0 0 0" rpy="0 0 0"/>
		<geometry>
			<box size="0.05 0.05 0.05"/>
		</geometry>	
	</visual>
  	<collision name="camera_collision">
		<origin xyz="0 0 0" rpy="0 0 0"/>
		<geometry>
			<box size="0.05 0.05 0.05"/>
		</geometry>	
	</collision>
  </link>

  <joint type="fixed" name="camera_joint">
    <origin xyz="0.4 0 0" rpy="0 0 0"/>
    <child link="camera"/>
    <parent link="chassis"/>
    <axis xyz="0 1 0" rpy="0 0 0"/>
  </joint>

  <link name="hokuyo">	
	<inertial>
	      <mass value="1e-5"/>
	      <origin xyz="0 0 0" rpy="0 0 0"/>
      		<inertia ixx="1e-6" ixy="0" ixz="0" iyy="1e-6" iyz="0" izz="1e-6"/>
    	</inertial>
  	<visual name="hokuyo_visual">
		<origin xyz="0 0 0" rpy="0 0 0"/>
		<geometry>
			<!--box size=".2 .2 .2"/-->
			<mesh filename="package://my_robot/meshes/hokuyo.dae"/>	
		</geometry>	
	</visual>
  	<collision name="hokuyo_collision">
		<origin xyz="0 0 0" rpy="0 0 0"/>
		<geometry>
			<box size=".1 .1 .1"/>
		</geometry>	
	</collision>
  </link>

  <joint type="fixed" name="hokuyo_joint">
    <origin xyz="0.35 0 0.1" rpy="0 0 0"/>
    <child link="hokuyo"/>
    <parent link="chassis"/>
    <axis xyz="0 1 0" rpy="0 0 0"/>
  </joint>

</robot>
